I'm sorry, but an uncaught exception occurred.

While running game code:
  File "game/script.rpy", line 221, in script
    with Shake((0, 0, 0, 0), 1.0, dist=10)
  File "game/script.rpy", line 221, in <module>
    with Shake((0, 0, 0, 0), 1.0, dist=10)
NameError: name 'Shake' is not defined

-- Full Traceback ------------------------------------------------------------

Full traceback:
  File "game/script.rpy", line 221, in script
    with Shake((0, 0, 0, 0), 1.0, dist=10)
  File "D:\game\renpy-8.0.3-sdk\renpy\ast.py", line 1651, in execute
    trans = renpy.python.py_eval(self.expr)
  File "D:\game\renpy-8.0.3-sdk\renpy\python.py", line 1092, in py_eval
    return py_eval_bytecode(code, globals, locals)
  File "D:\game\renpy-8.0.3-sdk\renpy\python.py", line 1085, in py_eval_bytecode
    return eval(bytecode, globals, locals)
  File "game/script.rpy", line 221, in <module>
    with Shake((0, 0, 0, 0), 1.0, dist=10)
NameError: name 'Shake' is not defined

Windows-10-10.0.22621 AMD64
Ren'Py 8.0.3.22090809
异世界的雪与奇迹 
Wed Jun  7 19:13:45 2023
